[2022-02-07 12:11:11,638] {taskinstance.py:1032} INFO - Dependencies all met for <TaskInstance: yellowTX_HW_data_ingestion_gcs_dag.download_dataset_task scheduled__2020-07-01T23:00:00+00:00 [queued]>
[2022-02-07 12:11:11,740] {taskinstance.py:1032} INFO - Dependencies all met for <TaskInstance: yellowTX_HW_data_ingestion_gcs_dag.download_dataset_task scheduled__2020-07-01T23:00:00+00:00 [queued]>
[2022-02-07 12:11:11,740] {taskinstance.py:1238} INFO - 
--------------------------------------------------------------------------------
[2022-02-07 12:11:11,740] {taskinstance.py:1239} INFO - Starting attempt 1 of 1
[2022-02-07 12:11:11,740] {taskinstance.py:1240} INFO - 
--------------------------------------------------------------------------------
[2022-02-07 12:11:11,870] {taskinstance.py:1259} INFO - Executing <Task(BashOperator): download_dataset_task> on 2020-07-01 23:00:00+00:00
[2022-02-07 12:11:11,914] {standard_task_runner.py:52} INFO - Started process 2216 to run task
[2022-02-07 12:11:12,007] {standard_task_runner.py:76} INFO - Running: ['***', 'tasks', 'run', 'yellowTX_HW_data_ingestion_gcs_dag', 'download_dataset_task', 'scheduled__2020-07-01T23:00:00+00:00', '--job-id', '46', '--raw', '--subdir', 'DAGS_FOLDER/yellowTX_data_ingest_gcs_dag.py', '--cfg-path', '/tmp/tmps470bwax', '--error-file', '/tmp/tmptb6znivp']
[2022-02-07 12:11:12,015] {standard_task_runner.py:77} INFO - Job 46: Subtask download_dataset_task
[2022-02-07 12:11:12,608] {logging_mixin.py:109} INFO - Running <TaskInstance: yellowTX_HW_data_ingestion_gcs_dag.download_dataset_task scheduled__2020-07-01T23:00:00+00:00 [running]> on host 52b8b55537b2
[2022-02-07 12:11:12,869] {warnings.py:110} WARNING - /home/***/.local/lib/python3.7/site-packages/***/utils/context.py:152: AirflowContextDeprecationWarning: Accessing 'execution_date' from the template is deprecated and will be removed in a future version. Please use 'data_interval_start' or 'logical_date' instead.
  warnings.warn(_create_deprecation_warning(key, self._deprecation_replacements[key]))

[2022-02-07 12:11:13,208] {taskinstance.py:1426} INFO - Exporting the following env vars:
AIRFLOW_CTX_DAG_OWNER=***
AIRFLOW_CTX_DAG_ID=yellowTX_HW_data_ingestion_gcs_dag
AIRFLOW_CTX_TASK_ID=download_dataset_task
AIRFLOW_CTX_EXECUTION_DATE=2020-07-01T23:00:00+00:00
AIRFLOW_CTX_DAG_RUN_ID=scheduled__2020-07-01T23:00:00+00:00
[2022-02-07 12:11:13,209] {subprocess.py:62} INFO - Tmp dir root location: 
 /tmp
[2022-02-07 12:11:13,210] {subprocess.py:74} INFO - Running command: ['bash', '-c', 'curl -sSL https://s3.amazonaws.com/nyc-tlc/trip+data/yellow_tripdata_2020-07.csv > /opt/***/yellow_tripdata_2020-07.csv']
[2022-02-07 12:11:13,232] {subprocess.py:85} INFO - Output:
[2022-02-07 12:11:15,407] {subprocess.py:93} INFO - Command exited with return code 0
[2022-02-07 12:11:15,546] {taskinstance.py:1277} INFO - Marking task as SUCCESS. dag_id=yellowTX_HW_data_ingestion_gcs_dag, task_id=download_dataset_task, execution_date=20200701T230000, start_date=20220207T121111, end_date=20220207T121115
[2022-02-07 12:11:15,846] {local_task_job.py:154} INFO - Task exited with return code 0
[2022-02-07 12:11:15,982] {local_task_job.py:264} INFO - 1 downstream tasks scheduled from follow-on schedule check
[2022-02-07 12:44:03,395] {taskinstance.py:1032} INFO - Dependencies all met for <TaskInstance: yellowTX_HW_data_ingestion_gcs_dag.download_dataset_task scheduled__2020-07-01T23:00:00+00:00 [queued]>
[2022-02-07 12:44:03,608] {taskinstance.py:1032} INFO - Dependencies all met for <TaskInstance: yellowTX_HW_data_ingestion_gcs_dag.download_dataset_task scheduled__2020-07-01T23:00:00+00:00 [queued]>
[2022-02-07 12:44:03,608] {taskinstance.py:1238} INFO - 
--------------------------------------------------------------------------------
[2022-02-07 12:44:03,608] {taskinstance.py:1239} INFO - Starting attempt 1 of 1
[2022-02-07 12:44:03,608] {taskinstance.py:1240} INFO - 
--------------------------------------------------------------------------------
[2022-02-07 12:44:04,217] {taskinstance.py:1259} INFO - Executing <Task(BashOperator): download_dataset_task> on 2020-07-01 23:00:00+00:00
[2022-02-07 12:44:04,277] {standard_task_runner.py:52} INFO - Started process 701 to run task
[2022-02-07 12:44:04,322] {standard_task_runner.py:76} INFO - Running: ['***', 'tasks', 'run', 'yellowTX_HW_data_ingestion_gcs_dag', 'download_dataset_task', 'scheduled__2020-07-01T23:00:00+00:00', '--job-id', '127', '--raw', '--subdir', 'DAGS_FOLDER/yellowTX_data_ingest_gcs_dag.py', '--cfg-path', '/tmp/tmpirtfc4km', '--error-file', '/tmp/tmpaqa4cjk2']
[2022-02-07 12:44:04,338] {standard_task_runner.py:77} INFO - Job 127: Subtask download_dataset_task
[2022-02-07 12:44:05,585] {logging_mixin.py:109} INFO - Running <TaskInstance: yellowTX_HW_data_ingestion_gcs_dag.download_dataset_task scheduled__2020-07-01T23:00:00+00:00 [running]> on host 4f748fac91e5
[2022-02-07 12:44:08,570] {warnings.py:110} WARNING - /home/***/.local/lib/python3.7/site-packages/***/utils/context.py:152: AirflowContextDeprecationWarning: Accessing 'execution_date' from the template is deprecated and will be removed in a future version. Please use 'data_interval_start' or 'logical_date' instead.
  warnings.warn(_create_deprecation_warning(key, self._deprecation_replacements[key]))

[2022-02-07 12:44:08,795] {taskinstance.py:1426} INFO - Exporting the following env vars:
AIRFLOW_CTX_DAG_OWNER=***
AIRFLOW_CTX_DAG_ID=yellowTX_HW_data_ingestion_gcs_dag
AIRFLOW_CTX_TASK_ID=download_dataset_task
AIRFLOW_CTX_EXECUTION_DATE=2020-07-01T23:00:00+00:00
AIRFLOW_CTX_DAG_RUN_ID=scheduled__2020-07-01T23:00:00+00:00
[2022-02-07 12:44:09,000] {subprocess.py:62} INFO - Tmp dir root location: 
 /tmp
[2022-02-07 12:44:09,343] {subprocess.py:74} INFO - Running command: ['bash', '-c', 'curl -sSL https://s3.amazonaws.com/nyc-tlc/trip+data/yellow_tripdata_2020-07.csv > /opt/***/yellow_tripdata_2020-07.csv']
[2022-02-07 12:44:09,430] {subprocess.py:85} INFO - Output:
[2022-02-07 13:03:27,521] {base_job.py:230} ERROR - LocalTaskJob heartbeat got an exception
Traceback (most recent call last):
  File "/home/airflow/.local/lib/python3.7/site-packages/sqlalchemy/engine/base.py", line 2336, in _wrap_pool_connect
    return fn()
  File "/home/airflow/.local/lib/python3.7/site-packages/sqlalchemy/pool/base.py", line 364, in connect
    return _ConnectionFairy._checkout(self)
  File "/home/airflow/.local/lib/python3.7/site-packages/sqlalchemy/pool/base.py", line 778, in _checkout
    fairy = _ConnectionRecord.checkout(pool)
  File "/home/airflow/.local/lib/python3.7/site-packages/sqlalchemy/pool/base.py", line 495, in checkout
    rec = pool._do_get()
  File "/home/airflow/.local/lib/python3.7/site-packages/sqlalchemy/pool/impl.py", line 241, in _do_get
    return self._create_connection()
  File "/home/airflow/.local/lib/python3.7/site-packages/sqlalchemy/pool/base.py", line 309, in _create_connection
    return _ConnectionRecord(self)
  File "/home/airflow/.local/lib/python3.7/site-packages/sqlalchemy/pool/base.py", line 440, in __init__
    self.__connect(first_connect_check=True)
  File "/home/airflow/.local/lib/python3.7/site-packages/sqlalchemy/pool/base.py", line 661, in __connect
    pool.logger.debug("Error on connect(): %s", e)
  File "/home/airflow/.local/lib/python3.7/site-packages/sqlalchemy/util/langhelpers.py", line 70, in __exit__
    with_traceback=exc_tb,
  File "/home/airflow/.local/lib/python3.7/site-packages/sqlalchemy/util/compat.py", line 182, in raise_
    raise exception
  File "/home/airflow/.local/lib/python3.7/site-packages/sqlalchemy/pool/base.py", line 656, in __connect
    connection = pool._invoke_creator(self)
  File "/home/airflow/.local/lib/python3.7/site-packages/sqlalchemy/engine/strategies.py", line 114, in connect
    return dialect.connect(*cargs, **cparams)
  File "/home/airflow/.local/lib/python3.7/site-packages/sqlalchemy/engine/default.py", line 508, in connect
    return self.dbapi.connect(*cargs, **cparams)
  File "/home/airflow/.local/lib/python3.7/site-packages/psycopg2/__init__.py", line 122, in connect
    conn = _connect(dsn, connection_factory=connection_factory, **kwasync)
psycopg2.OperationalError: could not translate host name "postgres" to address: Temporary failure in name resolution


The above exception was the direct cause of the following exception:

Traceback (most recent call last):
  File "/home/airflow/.local/lib/python3.7/site-packages/airflow/jobs/base_job.py", line 220, in heartbeat
    session.merge(self)
  File "/home/airflow/.local/lib/python3.7/site-packages/sqlalchemy/orm/session.py", line 2171, in merge
    _resolve_conflict_map=_resolve_conflict_map,
  File "/home/airflow/.local/lib/python3.7/site-packages/sqlalchemy/orm/session.py", line 2244, in _merge
    merged = self.query(mapper.class_).get(key[1])
  File "/home/airflow/.local/lib/python3.7/site-packages/sqlalchemy/orm/query.py", line 1018, in get
    return self._get_impl(ident, loading.load_on_pk_identity)
  File "/home/airflow/.local/lib/python3.7/site-packages/sqlalchemy/orm/query.py", line 1135, in _get_impl
    return db_load_fn(self, primary_key_identity)
  File "/home/airflow/.local/lib/python3.7/site-packages/sqlalchemy/orm/loading.py", line 286, in load_on_pk_identity
    return q.one()
  File "/home/airflow/.local/lib/python3.7/site-packages/sqlalchemy/orm/query.py", line 3490, in one
    ret = self.one_or_none()
  File "/home/airflow/.local/lib/python3.7/site-packages/sqlalchemy/orm/query.py", line 3459, in one_or_none
    ret = list(self)
  File "/home/airflow/.local/lib/python3.7/site-packages/sqlalchemy/orm/query.py", line 3535, in __iter__
    return self._execute_and_instances(context)
  File "/home/airflow/.local/lib/python3.7/site-packages/sqlalchemy/orm/query.py", line 3557, in _execute_and_instances
    querycontext, self._connection_from_session, close_with_result=True
  File "/home/airflow/.local/lib/python3.7/site-packages/sqlalchemy/orm/query.py", line 3572, in _get_bind_args
    mapper=self._bind_mapper(), clause=querycontext.statement, **kw
  File "/home/airflow/.local/lib/python3.7/site-packages/sqlalchemy/orm/query.py", line 3550, in _connection_from_session
    conn = self.session.connection(**kw)
  File "/home/airflow/.local/lib/python3.7/site-packages/sqlalchemy/orm/session.py", line 1145, in connection
    execution_options=execution_options,
  File "/home/airflow/.local/lib/python3.7/site-packages/sqlalchemy/orm/session.py", line 1151, in _connection_for_bind
    engine, execution_options
  File "/home/airflow/.local/lib/python3.7/site-packages/sqlalchemy/orm/session.py", line 433, in _connection_for_bind
    conn = bind._contextual_connect()
  File "/home/airflow/.local/lib/python3.7/site-packages/sqlalchemy/engine/base.py", line 2302, in _contextual_connect
    self._wrap_pool_connect(self.pool.connect, None),
  File "/home/airflow/.local/lib/python3.7/site-packages/sqlalchemy/engine/base.py", line 2340, in _wrap_pool_connect
    e, dialect, self
  File "/home/airflow/.local/lib/python3.7/site-packages/sqlalchemy/engine/base.py", line 1584, in _handle_dbapi_exception_noconnection
    sqlalchemy_exception, with_traceback=exc_info[2], from_=e
  File "/home/airflow/.local/lib/python3.7/site-packages/sqlalchemy/util/compat.py", line 182, in raise_
    raise exception
  File "/home/airflow/.local/lib/python3.7/site-packages/sqlalchemy/engine/base.py", line 2336, in _wrap_pool_connect
    return fn()
  File "/home/airflow/.local/lib/python3.7/site-packages/sqlalchemy/pool/base.py", line 364, in connect
    return _ConnectionFairy._checkout(self)
  File "/home/airflow/.local/lib/python3.7/site-packages/sqlalchemy/pool/base.py", line 778, in _checkout
    fairy = _ConnectionRecord.checkout(pool)
  File "/home/airflow/.local/lib/python3.7/site-packages/sqlalchemy/pool/base.py", line 495, in checkout
    rec = pool._do_get()
  File "/home/airflow/.local/lib/python3.7/site-packages/sqlalchemy/pool/impl.py", line 241, in _do_get
    return self._create_connection()
  File "/home/airflow/.local/lib/python3.7/site-packages/sqlalchemy/pool/base.py", line 309, in _create_connection
    return _ConnectionRecord(self)
  File "/home/airflow/.local/lib/python3.7/site-packages/sqlalchemy/pool/base.py", line 440, in __init__
    self.__connect(first_connect_check=True)
  File "/home/airflow/.local/lib/python3.7/site-packages/sqlalchemy/pool/base.py", line 661, in __connect
    pool.logger.debug("Error on connect(): %s", e)
  File "/home/airflow/.local/lib/python3.7/site-packages/sqlalchemy/util/langhelpers.py", line 70, in __exit__
    with_traceback=exc_tb,
  File "/home/airflow/.local/lib/python3.7/site-packages/sqlalchemy/util/compat.py", line 182, in raise_
    raise exception
  File "/home/airflow/.local/lib/python3.7/site-packages/sqlalchemy/pool/base.py", line 656, in __connect
    connection = pool._invoke_creator(self)
  File "/home/airflow/.local/lib/python3.7/site-packages/sqlalchemy/engine/strategies.py", line 114, in connect
    return dialect.connect(*cargs, **cparams)
  File "/home/airflow/.local/lib/python3.7/site-packages/sqlalchemy/engine/default.py", line 508, in connect
    return self.dbapi.connect(*cargs, **cparams)
  File "/home/airflow/.local/lib/python3.7/site-packages/psycopg2/__init__.py", line 122, in connect
    conn = _connect(dsn, connection_factory=connection_factory, **kwasync)
sqlalchemy.exc.OperationalError: (psycopg2.OperationalError) could not translate host name "postgres" to address: Temporary failure in name resolution

(Background on this error at: http://sqlalche.me/e/13/e3q8)
[2022-02-07 13:05:07,831] {local_task_job.py:142} ERROR - Heartbeat time limit exceeded!
[2022-02-07 13:05:21,098] {process_utils.py:124} INFO - Sending Signals.SIGTERM to group 701. PIDs of all processes in the group: [703, 704, 701]
[2022-02-07 13:05:26,950] {process_utils.py:75} INFO - Sending the signal Signals.SIGTERM to group 701
[2022-02-07 13:06:01,241] {taskinstance.py:1408} ERROR - Received SIGTERM. Terminating subprocesses.
[2022-02-07 13:06:20,797] {subprocess.py:99} INFO - Sending SIGTERM signal to process group
[2022-02-07 13:06:42,896] {process_utils.py:70} INFO - Process psutil.Process(pid=704, status='terminated', started='12:44:09') (704) terminated with exit code None
[2022-02-07 13:07:52,494] {process_utils.py:138} WARNING - process psutil.Process(pid=703, name='bash', status='zombie', started='12:44:09') did not respond to SIGTERM. Trying SIGKILL
[2022-02-07 13:13:58,559] {process_utils.py:138} WARNING - process psutil.Process(pid=701, name='airflow task ru', status='disk-sleep', started='12:44:03') did not respond to SIGTERM. Trying SIGKILL
[2022-02-07 13:13:59,710] {process_utils.py:75} INFO - Sending the signal Signals.SIGKILL to group 701
[2022-02-07 13:13:59,787] {process_utils.py:70} INFO - Process psutil.Process(pid=701, name='airflow task ru', status='terminated', exitcode=<Negsignal.SIGKILL: -9>, started='12:44:03') (701) terminated with exit code Negsignal.SIGKILL
[2022-02-07 13:13:59,999] {process_utils.py:70} INFO - Process psutil.Process(pid=703, name='bash', status='terminated', started='12:44:09') (703) terminated with exit code None
[2022-02-07 13:14:00,000] {standard_task_runner.py:135} ERROR - Job 127 was killed before it finished (likely due to running out of memory)
