[2022-02-07 12:12:58,464] {taskinstance.py:1032} INFO - Dependencies all met for <TaskInstance: yellowTX_HW_data_ingestion_gcs_dag.local_to_gcs_task scheduled__2021-10-01T23:00:00+00:00 [queued]>
[2022-02-07 12:12:58,641] {taskinstance.py:1032} INFO - Dependencies all met for <TaskInstance: yellowTX_HW_data_ingestion_gcs_dag.local_to_gcs_task scheduled__2021-10-01T23:00:00+00:00 [queued]>
[2022-02-07 12:12:58,642] {taskinstance.py:1238} INFO - 
--------------------------------------------------------------------------------
[2022-02-07 12:12:58,642] {taskinstance.py:1239} INFO - Starting attempt 1 of 1
[2022-02-07 12:12:58,642] {taskinstance.py:1240} INFO - 
--------------------------------------------------------------------------------
[2022-02-07 12:13:00,446] {taskinstance.py:1259} INFO - Executing <Task(PythonOperator): local_to_gcs_task> on 2021-10-01 23:00:00+00:00
[2022-02-07 12:13:00,543] {standard_task_runner.py:52} INFO - Started process 2469 to run task
[2022-02-07 12:13:00,629] {standard_task_runner.py:76} INFO - Running: ['***', 'tasks', 'run', 'yellowTX_HW_data_ingestion_gcs_dag', 'local_to_gcs_task', 'scheduled__2021-10-01T23:00:00+00:00', '--job-id', '72', '--raw', '--subdir', 'DAGS_FOLDER/yellowTX_data_ingest_gcs_dag.py', '--cfg-path', '/tmp/tmpiku1on2v', '--error-file', '/tmp/tmpi3lz3tab']
[2022-02-07 12:13:00,673] {standard_task_runner.py:77} INFO - Job 72: Subtask local_to_gcs_task
[2022-02-07 12:13:01,535] {logging_mixin.py:109} INFO - Running <TaskInstance: yellowTX_HW_data_ingestion_gcs_dag.local_to_gcs_task scheduled__2021-10-01T23:00:00+00:00 [running]> on host 52b8b55537b2
[2022-02-07 12:13:01,784] {warnings.py:110} WARNING - /home/***/.local/lib/python3.7/site-packages/***/utils/context.py:152: AirflowContextDeprecationWarning: Accessing 'execution_date' from the template is deprecated and will be removed in a future version. Please use 'data_interval_start' or 'logical_date' instead.
  warnings.warn(_create_deprecation_warning(key, self._deprecation_replacements[key]))

[2022-02-07 12:13:01,884] {taskinstance.py:1426} INFO - Exporting the following env vars:
AIRFLOW_CTX_DAG_OWNER=***
AIRFLOW_CTX_DAG_ID=yellowTX_HW_data_ingestion_gcs_dag
AIRFLOW_CTX_TASK_ID=local_to_gcs_task
AIRFLOW_CTX_EXECUTION_DATE=2021-10-01T23:00:00+00:00
AIRFLOW_CTX_DAG_RUN_ID=scheduled__2021-10-01T23:00:00+00:00
[2022-02-07 12:13:02,598] {taskinstance.py:1700} ERROR - Task failed with exception
Traceback (most recent call last):
  File "/home/airflow/.local/lib/python3.7/site-packages/google/cloud/storage/blob.py", line 2594, in upload_from_file
    retry=retry,
  File "/home/airflow/.local/lib/python3.7/site-packages/google/cloud/storage/blob.py", line 2396, in _do_upload
    retry=retry,
  File "/home/airflow/.local/lib/python3.7/site-packages/google/cloud/storage/blob.py", line 1917, in _do_multipart_upload
    transport, data, object_metadata, content_type, timeout=timeout
  File "/home/airflow/.local/lib/python3.7/site-packages/google/resumable_media/requests/upload.py", line 154, in transmit
    retriable_request, self._get_status_code, self._retry_strategy
  File "/home/airflow/.local/lib/python3.7/site-packages/google/resumable_media/requests/_request_helpers.py", line 147, in wait_and_retry
    response = func()
  File "/home/airflow/.local/lib/python3.7/site-packages/google/resumable_media/requests/upload.py", line 149, in retriable_request
    self._process_response(result)
  File "/home/airflow/.local/lib/python3.7/site-packages/google/resumable_media/_upload.py", line 113, in _process_response
    _helpers.require_status_code(response, (http.client.OK,), self._get_status_code)
  File "/home/airflow/.local/lib/python3.7/site-packages/google/resumable_media/_helpers.py", line 104, in require_status_code
    *status_codes
google.resumable_media.common.InvalidResponse: ('Request failed with status code', 403, 'Expected one of', <HTTPStatus.OK: 200>)

During handling of the above exception, another exception occurred:

Traceback (most recent call last):
  File "/home/airflow/.local/lib/python3.7/site-packages/airflow/models/taskinstance.py", line 1329, in _run_raw_task
    self._execute_task_with_callbacks(context)
  File "/home/airflow/.local/lib/python3.7/site-packages/airflow/models/taskinstance.py", line 1455, in _execute_task_with_callbacks
    result = self._execute_task(context, self.task)
  File "/home/airflow/.local/lib/python3.7/site-packages/airflow/models/taskinstance.py", line 1511, in _execute_task
    result = execute_callable(context=context)
  File "/home/airflow/.local/lib/python3.7/site-packages/airflow/operators/python.py", line 174, in execute
    return_value = self.execute_callable()
  File "/home/airflow/.local/lib/python3.7/site-packages/airflow/operators/python.py", line 185, in execute_callable
    return self.python_callable(*self.op_args, **self.op_kwargs)
  File "/opt/airflow/dags/yellowTX_data_ingest_gcs_dag.py", line 58, in upload_to_gcs
    blob.upload_from_filename(local_file)
  File "/home/airflow/.local/lib/python3.7/site-packages/google/cloud/storage/blob.py", line 2735, in upload_from_filename
    retry=retry,
  File "/home/airflow/.local/lib/python3.7/site-packages/google/cloud/storage/blob.py", line 2598, in upload_from_file
    _raise_from_invalid_response(exc)
  File "/home/airflow/.local/lib/python3.7/site-packages/google/cloud/storage/blob.py", line 4466, in _raise_from_invalid_response
    raise exceptions.from_http_status(response.status_code, message, response=response)
google.api_core.exceptions.Forbidden: 403 POST https://storage.googleapis.com/upload/storage/v1/b/dtc_data_lake_pivotal-surfer-336713/o?uploadType=multipart: {
  "error": {
    "code": 403,
    "message": "dtc-de-user@data-zoomcamp-338514.iam.gserviceaccount.com does not have storage.objects.create access to the Google Cloud Storage object.",
    "errors": [
      {
        "message": "dtc-de-user@data-zoomcamp-338514.iam.gserviceaccount.com does not have storage.objects.create access to the Google Cloud Storage object.",
        "domain": "global",
        "reason": "forbidden"
      }
    ]
  }
}
: ('Request failed with status code', 403, 'Expected one of', <HTTPStatus.OK: 200>)
[2022-02-07 12:13:02,714] {taskinstance.py:1277} INFO - Marking task as FAILED. dag_id=yellowTX_HW_data_ingestion_gcs_dag, task_id=local_to_gcs_task, execution_date=20211001T230000, start_date=20220207T121258, end_date=20220207T121302
[2022-02-07 12:13:02,903] {standard_task_runner.py:92} ERROR - Failed to execute job 72 for task local_to_gcs_task
Traceback (most recent call last):
  File "/home/airflow/.local/lib/python3.7/site-packages/google/cloud/storage/blob.py", line 2594, in upload_from_file
    retry=retry,
  File "/home/airflow/.local/lib/python3.7/site-packages/google/cloud/storage/blob.py", line 2396, in _do_upload
    retry=retry,
  File "/home/airflow/.local/lib/python3.7/site-packages/google/cloud/storage/blob.py", line 1917, in _do_multipart_upload
    transport, data, object_metadata, content_type, timeout=timeout
  File "/home/airflow/.local/lib/python3.7/site-packages/google/resumable_media/requests/upload.py", line 154, in transmit
    retriable_request, self._get_status_code, self._retry_strategy
  File "/home/airflow/.local/lib/python3.7/site-packages/google/resumable_media/requests/_request_helpers.py", line 147, in wait_and_retry
    response = func()
  File "/home/airflow/.local/lib/python3.7/site-packages/google/resumable_media/requests/upload.py", line 149, in retriable_request
    self._process_response(result)
  File "/home/airflow/.local/lib/python3.7/site-packages/google/resumable_media/_upload.py", line 113, in _process_response
    _helpers.require_status_code(response, (http.client.OK,), self._get_status_code)
  File "/home/airflow/.local/lib/python3.7/site-packages/google/resumable_media/_helpers.py", line 104, in require_status_code
    *status_codes
google.resumable_media.common.InvalidResponse: ('Request failed with status code', 403, 'Expected one of', <HTTPStatus.OK: 200>)

During handling of the above exception, another exception occurred:

Traceback (most recent call last):
  File "/home/airflow/.local/lib/python3.7/site-packages/airflow/task/task_runner/standard_task_runner.py", line 85, in _start_by_fork
    args.func(args, dag=self.dag)
  File "/home/airflow/.local/lib/python3.7/site-packages/airflow/cli/cli_parser.py", line 48, in command
    return func(*args, **kwargs)
  File "/home/airflow/.local/lib/python3.7/site-packages/airflow/utils/cli.py", line 92, in wrapper
    return f(*args, **kwargs)
  File "/home/airflow/.local/lib/python3.7/site-packages/airflow/cli/commands/task_command.py", line 298, in task_run
    _run_task_by_selected_method(args, dag, ti)
  File "/home/airflow/.local/lib/python3.7/site-packages/airflow/cli/commands/task_command.py", line 107, in _run_task_by_selected_method
    _run_raw_task(args, ti)
  File "/home/airflow/.local/lib/python3.7/site-packages/airflow/cli/commands/task_command.py", line 184, in _run_raw_task
    error_file=args.error_file,
  File "/home/airflow/.local/lib/python3.7/site-packages/airflow/utils/session.py", line 70, in wrapper
    return func(*args, session=session, **kwargs)
  File "/home/airflow/.local/lib/python3.7/site-packages/airflow/models/taskinstance.py", line 1329, in _run_raw_task
    self._execute_task_with_callbacks(context)
  File "/home/airflow/.local/lib/python3.7/site-packages/airflow/models/taskinstance.py", line 1455, in _execute_task_with_callbacks
    result = self._execute_task(context, self.task)
  File "/home/airflow/.local/lib/python3.7/site-packages/airflow/models/taskinstance.py", line 1511, in _execute_task
    result = execute_callable(context=context)
  File "/home/airflow/.local/lib/python3.7/site-packages/airflow/operators/python.py", line 174, in execute
    return_value = self.execute_callable()
  File "/home/airflow/.local/lib/python3.7/site-packages/airflow/operators/python.py", line 185, in execute_callable
    return self.python_callable(*self.op_args, **self.op_kwargs)
  File "/opt/airflow/dags/yellowTX_data_ingest_gcs_dag.py", line 58, in upload_to_gcs
    blob.upload_from_filename(local_file)
  File "/home/airflow/.local/lib/python3.7/site-packages/google/cloud/storage/blob.py", line 2735, in upload_from_filename
    retry=retry,
  File "/home/airflow/.local/lib/python3.7/site-packages/google/cloud/storage/blob.py", line 2598, in upload_from_file
    _raise_from_invalid_response(exc)
  File "/home/airflow/.local/lib/python3.7/site-packages/google/cloud/storage/blob.py", line 4466, in _raise_from_invalid_response
    raise exceptions.from_http_status(response.status_code, message, response=response)
google.api_core.exceptions.Forbidden: 403 POST https://storage.googleapis.com/upload/storage/v1/b/dtc_data_lake_pivotal-surfer-336713/o?uploadType=multipart: {
  "error": {
    "code": 403,
    "message": "dtc-de-user@data-zoomcamp-338514.iam.gserviceaccount.com does not have storage.objects.create access to the Google Cloud Storage object.",
    "errors": [
      {
        "message": "dtc-de-user@data-zoomcamp-338514.iam.gserviceaccount.com does not have storage.objects.create access to the Google Cloud Storage object.",
        "domain": "global",
        "reason": "forbidden"
      }
    ]
  }
}
: ('Request failed with status code', 403, 'Expected one of', <HTTPStatus.OK: 200>)
[2022-02-07 12:13:03,051] {local_task_job.py:154} INFO - Task exited with return code 1
[2022-02-07 12:13:03,674] {local_task_job.py:264} INFO - 0 downstream tasks scheduled from follow-on schedule check
