[2022-02-09 12:06:45,602] {taskinstance.py:1032} INFO - Dependencies all met for <TaskInstance: FHV_data_HW_ingestion_gcs_dag.format_to_parquet_task scheduled__2020-01-01T23:00:00+00:00 [queued]>
[2022-02-09 12:06:45,619] {taskinstance.py:1032} INFO - Dependencies all met for <TaskInstance: FHV_data_HW_ingestion_gcs_dag.format_to_parquet_task scheduled__2020-01-01T23:00:00+00:00 [queued]>
[2022-02-09 12:06:45,619] {taskinstance.py:1238} INFO - 
--------------------------------------------------------------------------------
[2022-02-09 12:06:45,619] {taskinstance.py:1239} INFO - Starting attempt 5 of 5
[2022-02-09 12:06:45,619] {taskinstance.py:1240} INFO - 
--------------------------------------------------------------------------------
[2022-02-09 12:06:45,633] {taskinstance.py:1259} INFO - Executing <Task(PythonOperator): format_to_parquet_task> on 2020-01-01 23:00:00+00:00
[2022-02-09 12:06:45,639] {standard_task_runner.py:52} INFO - Started process 114 to run task
[2022-02-09 12:06:45,645] {standard_task_runner.py:76} INFO - Running: ['***', 'tasks', 'run', 'FHV_data_HW_ingestion_gcs_dag', 'format_to_parquet_task', 'scheduled__2020-01-01T23:00:00+00:00', '--job-id', '1010', '--raw', '--subdir', 'DAGS_FOLDER/FHV_data_ingest_gcs_dag.py', '--cfg-path', '/tmp/tmpybbl14uf', '--error-file', '/tmp/tmpk72deps1']
[2022-02-09 12:06:45,646] {standard_task_runner.py:77} INFO - Job 1010: Subtask format_to_parquet_task
[2022-02-09 12:06:45,719] {logging_mixin.py:109} INFO - Running <TaskInstance: FHV_data_HW_ingestion_gcs_dag.format_to_parquet_task scheduled__2020-01-01T23:00:00+00:00 [running]> on host 2b984638caa6
[2022-02-09 12:06:45,767] {warnings.py:110} WARNING - /home/***/.local/lib/python3.7/site-packages/***/utils/context.py:152: AirflowContextDeprecationWarning: Accessing 'execution_date' from the template is deprecated and will be removed in a future version. Please use 'data_interval_start' or 'logical_date' instead.
  warnings.warn(_create_deprecation_warning(key, self._deprecation_replacements[key]))

[2022-02-09 12:06:45,812] {taskinstance.py:1426} INFO - Exporting the following env vars:
AIRFLOW_CTX_DAG_OWNER=***
AIRFLOW_CTX_DAG_ID=FHV_data_HW_ingestion_gcs_dag
AIRFLOW_CTX_TASK_ID=format_to_parquet_task
AIRFLOW_CTX_EXECUTION_DATE=2020-01-01T23:00:00+00:00
AIRFLOW_CTX_DAG_RUN_ID=scheduled__2020-01-01T23:00:00+00:00
[2022-02-09 12:06:45,816] {taskinstance.py:1700} ERROR - Task failed with exception
Traceback (most recent call last):
  File "/home/airflow/.local/lib/python3.7/site-packages/airflow/models/taskinstance.py", line 1329, in _run_raw_task
    self._execute_task_with_callbacks(context)
  File "/home/airflow/.local/lib/python3.7/site-packages/airflow/models/taskinstance.py", line 1455, in _execute_task_with_callbacks
    result = self._execute_task(context, self.task)
  File "/home/airflow/.local/lib/python3.7/site-packages/airflow/models/taskinstance.py", line 1511, in _execute_task
    result = execute_callable(context=context)
  File "/home/airflow/.local/lib/python3.7/site-packages/airflow/operators/python.py", line 174, in execute
    return_value = self.execute_callable()
  File "/home/airflow/.local/lib/python3.7/site-packages/airflow/operators/python.py", line 185, in execute_callable
    return self.python_callable(*self.op_args, **self.op_kwargs)
  File "/opt/airflow/dags/FHV_data_ingest_gcs_dag.py", line 35, in format_to_parquet
    table = pv.read_csv(src_file)
  File "pyarrow/_csv.pyx", line 862, in pyarrow._csv.read_csv
  File "pyarrow/_csv.pyx", line 755, in pyarrow._csv._get_reader
  File "pyarrow/io.pxi", line 1551, in pyarrow.lib.get_input_stream
  File "pyarrow/io.pxi", line 1522, in pyarrow.lib.get_native_file
  File "pyarrow/io.pxi", line 886, in pyarrow.lib.OSFile.__cinit__
  File "pyarrow/io.pxi", line 896, in pyarrow.lib.OSFile._open_readable
  File "pyarrow/error.pxi", line 143, in pyarrow.lib.pyarrow_internal_check_status
  File "pyarrow/error.pxi", line 112, in pyarrow.lib.check_status
FileNotFoundError: [Errno 2] Failed to open local file '/opt/airflow/fhv_tripdata_2020-01.csv'. Detail: [errno 2] No such file or directory
[2022-02-09 12:06:45,835] {taskinstance.py:1277} INFO - Marking task as FAILED. dag_id=FHV_data_HW_ingestion_gcs_dag, task_id=format_to_parquet_task, execution_date=20200101T230000, start_date=20220209T120645, end_date=20220209T120645
[2022-02-09 12:06:45,850] {standard_task_runner.py:92} ERROR - Failed to execute job 1010 for task format_to_parquet_task
Traceback (most recent call last):
  File "/home/airflow/.local/lib/python3.7/site-packages/airflow/task/task_runner/standard_task_runner.py", line 85, in _start_by_fork
    args.func(args, dag=self.dag)
  File "/home/airflow/.local/lib/python3.7/site-packages/airflow/cli/cli_parser.py", line 48, in command
    return func(*args, **kwargs)
  File "/home/airflow/.local/lib/python3.7/site-packages/airflow/utils/cli.py", line 92, in wrapper
    return f(*args, **kwargs)
  File "/home/airflow/.local/lib/python3.7/site-packages/airflow/cli/commands/task_command.py", line 298, in task_run
    _run_task_by_selected_method(args, dag, ti)
  File "/home/airflow/.local/lib/python3.7/site-packages/airflow/cli/commands/task_command.py", line 107, in _run_task_by_selected_method
    _run_raw_task(args, ti)
  File "/home/airflow/.local/lib/python3.7/site-packages/airflow/cli/commands/task_command.py", line 184, in _run_raw_task
    error_file=args.error_file,
  File "/home/airflow/.local/lib/python3.7/site-packages/airflow/utils/session.py", line 70, in wrapper
    return func(*args, session=session, **kwargs)
  File "/home/airflow/.local/lib/python3.7/site-packages/airflow/models/taskinstance.py", line 1329, in _run_raw_task
    self._execute_task_with_callbacks(context)
  File "/home/airflow/.local/lib/python3.7/site-packages/airflow/models/taskinstance.py", line 1455, in _execute_task_with_callbacks
    result = self._execute_task(context, self.task)
  File "/home/airflow/.local/lib/python3.7/site-packages/airflow/models/taskinstance.py", line 1511, in _execute_task
    result = execute_callable(context=context)
  File "/home/airflow/.local/lib/python3.7/site-packages/airflow/operators/python.py", line 174, in execute
    return_value = self.execute_callable()
  File "/home/airflow/.local/lib/python3.7/site-packages/airflow/operators/python.py", line 185, in execute_callable
    return self.python_callable(*self.op_args, **self.op_kwargs)
  File "/opt/airflow/dags/FHV_data_ingest_gcs_dag.py", line 35, in format_to_parquet
    table = pv.read_csv(src_file)
  File "pyarrow/_csv.pyx", line 862, in pyarrow._csv.read_csv
  File "pyarrow/_csv.pyx", line 755, in pyarrow._csv._get_reader
  File "pyarrow/io.pxi", line 1551, in pyarrow.lib.get_input_stream
  File "pyarrow/io.pxi", line 1522, in pyarrow.lib.get_native_file
  File "pyarrow/io.pxi", line 886, in pyarrow.lib.OSFile.__cinit__
  File "pyarrow/io.pxi", line 896, in pyarrow.lib.OSFile._open_readable
  File "pyarrow/error.pxi", line 143, in pyarrow.lib.pyarrow_internal_check_status
  File "pyarrow/error.pxi", line 112, in pyarrow.lib.check_status
FileNotFoundError: [Errno 2] Failed to open local file '/opt/airflow/fhv_tripdata_2020-01.csv'. Detail: [errno 2] No such file or directory
[2022-02-09 12:06:45,897] {local_task_job.py:154} INFO - Task exited with return code 1
[2022-02-09 12:06:45,944] {local_task_job.py:264} INFO - 0 downstream tasks scheduled from follow-on schedule check
