[2022-02-09 09:38:06,076] {taskinstance.py:1032} INFO - Dependencies all met for <TaskInstance: yelloTaXii_HW_data_ingestion_gcs_dag.local_to_gcs_task scheduled__2021-03-01T23:00:00+00:00 [queued]>
[2022-02-09 09:38:06,095] {taskinstance.py:1032} INFO - Dependencies all met for <TaskInstance: yelloTaXii_HW_data_ingestion_gcs_dag.local_to_gcs_task scheduled__2021-03-01T23:00:00+00:00 [queued]>
[2022-02-09 09:38:06,096] {taskinstance.py:1238} INFO - 
--------------------------------------------------------------------------------
[2022-02-09 09:38:06,096] {taskinstance.py:1239} INFO - Starting attempt 2 of 2
[2022-02-09 09:38:06,096] {taskinstance.py:1240} INFO - 
--------------------------------------------------------------------------------
[2022-02-09 09:38:06,118] {taskinstance.py:1259} INFO - Executing <Task(PythonOperator): local_to_gcs_task> on 2021-03-01 23:00:00+00:00
[2022-02-09 09:38:06,127] {standard_task_runner.py:52} INFO - Started process 463 to run task
[2022-02-09 09:38:06,140] {standard_task_runner.py:76} INFO - Running: ['***', 'tasks', 'run', 'yelloTaXii_HW_data_ingestion_gcs_dag', 'local_to_gcs_task', 'scheduled__2021-03-01T23:00:00+00:00', '--job-id', '794', '--raw', '--subdir', 'DAGS_FOLDER/yelloTaXii_data_ingestion_gcs_dag.py', '--cfg-path', '/tmp/tmpzlczy4ni', '--error-file', '/tmp/tmpqdg2flbu']
[2022-02-09 09:38:06,142] {standard_task_runner.py:77} INFO - Job 794: Subtask local_to_gcs_task
[2022-02-09 09:38:06,295] {logging_mixin.py:109} INFO - Running <TaskInstance: yelloTaXii_HW_data_ingestion_gcs_dag.local_to_gcs_task scheduled__2021-03-01T23:00:00+00:00 [running]> on host fb702faa28b9
[2022-02-09 09:38:06,397] {warnings.py:110} WARNING - /home/***/.local/lib/python3.7/site-packages/***/utils/context.py:152: AirflowContextDeprecationWarning: Accessing 'execution_date' from the template is deprecated and will be removed in a future version. Please use 'data_interval_start' or 'logical_date' instead.
  warnings.warn(_create_deprecation_warning(key, self._deprecation_replacements[key]))

[2022-02-09 09:38:06,462] {taskinstance.py:1426} INFO - Exporting the following env vars:
AIRFLOW_CTX_DAG_OWNER=***
AIRFLOW_CTX_DAG_ID=yelloTaXii_HW_data_ingestion_gcs_dag
AIRFLOW_CTX_TASK_ID=local_to_gcs_task
AIRFLOW_CTX_EXECUTION_DATE=2021-03-01T23:00:00+00:00
AIRFLOW_CTX_DAG_RUN_ID=scheduled__2021-03-01T23:00:00+00:00
[2022-02-09 09:38:06,489] {taskinstance.py:1700} ERROR - Task failed with exception
Traceback (most recent call last):
  File "/home/airflow/.local/lib/python3.7/site-packages/airflow/models/taskinstance.py", line 1329, in _run_raw_task
    self._execute_task_with_callbacks(context)
  File "/home/airflow/.local/lib/python3.7/site-packages/airflow/models/taskinstance.py", line 1455, in _execute_task_with_callbacks
    result = self._execute_task(context, self.task)
  File "/home/airflow/.local/lib/python3.7/site-packages/airflow/models/taskinstance.py", line 1511, in _execute_task
    result = execute_callable(context=context)
  File "/home/airflow/.local/lib/python3.7/site-packages/airflow/operators/python.py", line 174, in execute
    return_value = self.execute_callable()
  File "/home/airflow/.local/lib/python3.7/site-packages/airflow/operators/python.py", line 185, in execute_callable
    return self.python_callable(*self.op_args, **self.op_kwargs)
  File "/opt/airflow/dags/yelloTaXii_data_ingestion_gcs_dag.py", line 58, in upload_to_gcs
    blob.upload_from_filename(local_file)
  File "/home/airflow/.local/lib/python3.7/site-packages/google/cloud/storage/blob.py", line 2720, in upload_from_filename
    with open(filename, "rb") as file_obj:
FileNotFoundError: [Errno 2] No such file or directory: '/opt/airflow/yellow_tripdata_2021-03.parquet'
[2022-02-09 09:38:06,518] {taskinstance.py:1277} INFO - Marking task as FAILED. dag_id=yelloTaXii_HW_data_ingestion_gcs_dag, task_id=local_to_gcs_task, execution_date=20210301T230000, start_date=20220209T093806, end_date=20220209T093806
[2022-02-09 09:38:06,552] {standard_task_runner.py:92} ERROR - Failed to execute job 794 for task local_to_gcs_task
Traceback (most recent call last):
  File "/home/airflow/.local/lib/python3.7/site-packages/airflow/task/task_runner/standard_task_runner.py", line 85, in _start_by_fork
    args.func(args, dag=self.dag)
  File "/home/airflow/.local/lib/python3.7/site-packages/airflow/cli/cli_parser.py", line 48, in command
    return func(*args, **kwargs)
  File "/home/airflow/.local/lib/python3.7/site-packages/airflow/utils/cli.py", line 92, in wrapper
    return f(*args, **kwargs)
  File "/home/airflow/.local/lib/python3.7/site-packages/airflow/cli/commands/task_command.py", line 298, in task_run
    _run_task_by_selected_method(args, dag, ti)
  File "/home/airflow/.local/lib/python3.7/site-packages/airflow/cli/commands/task_command.py", line 107, in _run_task_by_selected_method
    _run_raw_task(args, ti)
  File "/home/airflow/.local/lib/python3.7/site-packages/airflow/cli/commands/task_command.py", line 184, in _run_raw_task
    error_file=args.error_file,
  File "/home/airflow/.local/lib/python3.7/site-packages/airflow/utils/session.py", line 70, in wrapper
    return func(*args, session=session, **kwargs)
  File "/home/airflow/.local/lib/python3.7/site-packages/airflow/models/taskinstance.py", line 1329, in _run_raw_task
    self._execute_task_with_callbacks(context)
  File "/home/airflow/.local/lib/python3.7/site-packages/airflow/models/taskinstance.py", line 1455, in _execute_task_with_callbacks
    result = self._execute_task(context, self.task)
  File "/home/airflow/.local/lib/python3.7/site-packages/airflow/models/taskinstance.py", line 1511, in _execute_task
    result = execute_callable(context=context)
  File "/home/airflow/.local/lib/python3.7/site-packages/airflow/operators/python.py", line 174, in execute
    return_value = self.execute_callable()
  File "/home/airflow/.local/lib/python3.7/site-packages/airflow/operators/python.py", line 185, in execute_callable
    return self.python_callable(*self.op_args, **self.op_kwargs)
  File "/opt/airflow/dags/yelloTaXii_data_ingestion_gcs_dag.py", line 58, in upload_to_gcs
    blob.upload_from_filename(local_file)
  File "/home/airflow/.local/lib/python3.7/site-packages/google/cloud/storage/blob.py", line 2720, in upload_from_filename
    with open(filename, "rb") as file_obj:
FileNotFoundError: [Errno 2] No such file or directory: '/opt/airflow/yellow_tripdata_2021-03.parquet'
[2022-02-09 09:38:06,605] {local_task_job.py:154} INFO - Task exited with return code 1
[2022-02-09 09:38:06,672] {local_task_job.py:264} INFO - 0 downstream tasks scheduled from follow-on schedule check
